{"trial_id": "0", "hyperparameters": {"space": [{"class_name": "Choice", "config": {"name": "learning_rate", "default": 0.01, "conditions": [], "values": [0.01, 0.001, 0.0001], "ordered": true}}], "values": {"learning_rate": 0.001}}, "metrics": {"metrics": {}}, "score": null, "best_step": 0, "status": "FAILED", "message": "Traceback (most recent call last):\n  File \"C:\\ProgramData\\anaconda3\\lib\\site-packages\\keras_tuner\\engine\\base_tuner.py\", line 270, in _try_run_and_update_trial\n    self._run_and_update_trial(trial, *fit_args, **fit_kwargs)\n  File \"C:\\ProgramData\\anaconda3\\lib\\site-packages\\keras_tuner\\engine\\base_tuner.py\", line 235, in _run_and_update_trial\n    results = self.run_trial(trial, *fit_args, **fit_kwargs)\n  File \"C:\\ProgramData\\anaconda3\\lib\\site-packages\\keras_tuner\\engine\\tuner.py\", line 287, in run_trial\n    obj_value = self._build_and_fit_model(trial, *args, **copied_kwargs)\n  File \"C:\\ProgramData\\anaconda3\\lib\\site-packages\\keras_tuner\\engine\\tuner.py\", line 214, in _build_and_fit_model\n    results = self.hypermodel.fit(hp, model, *args, **kwargs)\n  File \"C:\\ProgramData\\anaconda3\\lib\\site-packages\\keras_tuner\\engine\\hypermodel.py\", line 144, in fit\n    return model.fit(*args, **kwargs)\n  File \"C:\\ProgramData\\anaconda3\\lib\\site-packages\\keras\\utils\\traceback_utils.py\", line 70, in error_handler\n    raise e.with_traceback(filtered_tb) from None\n  File \"C:\\Users\\Pinash\\AppData\\Local\\Temp\\__autograph_generated_fileii9k5scc.py\", line 15, in tf__train_function\n    retval_ = ag__.converted_call(ag__.ld(step_function), (ag__.ld(self), ag__.ld(iterator)), None, fscope)\nValueError: in user code:\n\n    File \"C:\\ProgramData\\anaconda3\\lib\\site-packages\\keras\\engine\\training.py\", line 1284, in train_function  *\n        return step_function(self, iterator)\n    File \"C:\\ProgramData\\anaconda3\\lib\\site-packages\\keras\\engine\\training.py\", line 1268, in step_function  **\n        outputs = model.distribute_strategy.run(run_step, args=(data,))\n    File \"C:\\ProgramData\\anaconda3\\lib\\site-packages\\keras\\engine\\training.py\", line 1249, in run_step  **\n        outputs = model.train_step(data)\n    File \"C:\\ProgramData\\anaconda3\\lib\\site-packages\\keras\\engine\\training.py\", line 1051, in train_step\n        loss = self.compute_loss(x, y, y_pred, sample_weight)\n    File \"C:\\ProgramData\\anaconda3\\lib\\site-packages\\keras\\engine\\training.py\", line 1109, in compute_loss\n        return self.compiled_loss(\n    File \"C:\\ProgramData\\anaconda3\\lib\\site-packages\\keras\\engine\\compile_utils.py\", line 265, in __call__\n        loss_value = loss_obj(y_t, y_p, sample_weight=sw)\n    File \"C:\\ProgramData\\anaconda3\\lib\\site-packages\\keras\\losses.py\", line 142, in __call__\n        losses = call_fn(y_true, y_pred)\n    File \"C:\\ProgramData\\anaconda3\\lib\\site-packages\\keras\\losses.py\", line 268, in call  **\n        return ag_fn(y_true, y_pred, **self._fn_kwargs)\n    File \"C:\\ProgramData\\anaconda3\\lib\\site-packages\\keras\\losses.py\", line 1984, in categorical_crossentropy\n        return backend.categorical_crossentropy(\n    File \"C:\\ProgramData\\anaconda3\\lib\\site-packages\\keras\\backend.py\", line 5559, in categorical_crossentropy\n        target.shape.assert_is_compatible_with(output.shape)\n\n    ValueError: Shapes (None, 6) and (None, 100, 300) are incompatible\n\n"}